<?xml version="1.0"?>
<robot name="jaco" 
  xmlns:xacro="http://ros.org/wiki/xacro">

 <xacro:property name="inertia" value="1" />
  <xacro:property name="finger_inertia" value="1" />

  <xacro:property name="PI" value="3.1415926535897931" />

<gazebo>
    <plugin filename="libgazebo_ros_controller_manager.so" name="gazebo_ros_controller_manager">
      <alwaysOn>true</alwaysOn>
      <updateRate>1000.0</updateRate>
      <robotParam>robot_description</robotParam>
    </plugin>
  </gazebo>


	<xacro:include filename="$(find jaco_description)/urdf/gazebo/jaco.gazebo.xacro" />
	<xacro:include filename="$(find jaco_description)/urdf/gazebo/jaco.transmissions.xacro" />

	<material name="JacoGrey">
	<color rgba="0.2 0.2 0.9 1.0"/>
	</material>

<!-- Used for fixing robot to Gazebo 'base_link' -->
  <link name="world"/>

  <joint name="fixed" type="fixed">
    <parent link="world"/>
    <child link="base_link"/>
  </joint>


  <link name="base_link"/>
  <joint name="base_joint" type="fixed">
    <parent link="world"/>
    <child link="jaco_base_link"/>
    <origin xyz="0 0 0.0"/>
  </joint>


  <link name="jaco_base_link" type="fixed">
    <inertial>
      <mass value="1"/>
      <!--origin xyz="0 0 -0.0525" rpy="0 0 0"/-->
      <origin rpy="0 0 0" xyz="0 0 0"/>
      <inertia ixx="1" ixy="0" ixz="0" iyy="1" iyz="0" izz="1"/>
    </inertial>
    <visual>
      <material name="JacoGrey"/>
      <!--origin xyz="0 0 -0.0525" rpy="0 0 0"/-->
      <geometry>
        <mesh filename="package://jaco_description/meshes/mico_joint_1.DAE" scale="1 1 1"/>
      </geometry>
    </visual>
    <collision>
      <!--origin xyz="0 0 -0.0525" rpy="0 0 0"/-->
      <geometry>
        <mesh filename="package://jaco_description/meshes/mico_joint_1.DAE" scale="1 1 1"/>
      </geometry>
    </collision>
   <parent link="base_link"/>
    <child link="jaco_link_1"/>
  </link>

  <gazebo reference="jaco_base_link">
    <material>Gazebo/Yellow</material>
    <turnGravityOff>true</turnGravityOff>
  </gazebo>

<joint name="jaco_joint_1" type="revolute">
    <!--origin xyz="0 0 0.2102" rpy="0 0 0"/-->
    <origin rpy="0 0 0" xyz="0 0 0.2775"/>
    <axis rpy="0 0 0" xyz="0 0 -1"/>
    <parent link="jaco_base_link"/>
    <child link="jaco_link_1"/>
    <limit effort="30" lower="-3.14159265359" upper="3.14159265359" velocity="5"/>
  </joint>

  <link name="jaco_link_1">
    <inertial>
      <mass value="1"/>
      <inertia ixx="1" ixy="0" ixz="0" iyy="1" iyz="0" izz="1"/>
      <origin/>
    </inertial>
    <visual>
      <material name="JacoGrey"/>
      <origin rpy="0 0 -1.570796327" xyz="0 0 -0.12"/>
      <geometry>
        <mesh filename="package://jaco_description/meshes/mico_joint_2.DAE" scale="1 1 1"/>
      </geometry>
    </visual>
    <collision>
      <origin rpy="0 0 -1.570796327" xyz="0 0 -0.12"/>
      <geometry>
        <mesh filename="package://jaco_description/meshes/mico_joint_2.DAE" scale="1 1 1"/>
      </geometry>
    </collision>
  </link>
  <gazebo reference="jaco_link_1">
    <material>Gazebo/Red</material>
    <turnGravityOff>false</turnGravityOff>
  </gazebo>

  <joint name="jaco_joint_2" type="revolute">
    <origin rpy="-1.570796327 0 0" xyz="0 -0.016 0"/>
    <axis xyz="0 0 1"/>
    <parent link="jaco_link_1"/>
    <child link="jaco_link_2"/>
    <limit effort="30" lower="-3.14159265359" upper="3.14159265359" velocity="5"/>
  </joint>
  <link name="jaco_link_2">
    <inertial>
      <mass value="1"/>
      <inertia ixx="1" ixy="0" ixz="0" iyy="1" iyz="0" izz="1"/>
      <origin/>
    </inertial>
    <visual>
      <material name="JacoGrey"/>
      <origin rpy="0 1.570796327 0" xyz="0 0 0.015"/>
      <geometry>
        <mesh filename="package://jaco_description/meshes/mico_joint_3.DAE" scale="1 1 1"/>
      </geometry>
    </visual>
    <collision>
      <origin rpy="0 1.570796327 0" xyz="0 0 0.015"/>
      <geometry>
        <mesh filename="package://jaco_description/meshes/mico_joint_3.DAE" scale="1 1 1"/>
      </geometry>
    </collision>
  </link>
  <gazebo reference="jaco_link_2">
    <material>Gazebo/Blue</material>
    <turnGravityOff>false</turnGravityOff>
  </gazebo>

  <joint name="jaco_joint_3" type="revolute">
    <origin rpy="0 0 0" xyz="0.2919 0 0.028"/>
    <axis xyz="0 0 -1"/>
    <parent link="jaco_link_2"/>
    <child link="jaco_link_3"/>
    <limit effort="30" lower="-3.14159265359" upper="3.14159265359" velocity="5"/>
  </joint>
  <link name="jaco_link_3">
    <inertial>
      <mass value="1"/>
      <inertia ixx="1" ixy="0" ixz="0" iyy="1" iyz="0" izz="1"/>
      <origin/>
    </inertial>
    <visual>
      <material name="JacoGrey"/>
      <origin rpy="0 1.570796327 1.570796327" xyz="0 0 -0.012"/>
      <geometry>
        <mesh filename="package://jaco_description/meshes/mico_joint_4.DAE" scale="1.000 1.000 1.000"/>
      </geometry>
    </visual>
    <collision>
      <origin rpy="0 1.570796327 1.570796327" xyz="0 0 -0.012"/>
      <geometry>
        <mesh filename="package://jaco_description/meshes/mico_joint_4.DAE" scale="1.000 1.000 1.000"/>
      </geometry>
    </collision>
  </link>
  <gazebo reference="jaco_link_3">
    <material>Gazebo/Red</material>
    <turnGravityOff>false</turnGravityOff>
  </gazebo>

  <joint name="jaco_joint_4" type="revolute">
    <origin rpy="-1.570796327 0 0" xyz="0 0.16555 -0.003 "/>
    <axis xyz="0 0 -1"/>
    <parent link="jaco_link_3"/>
    <child link="jaco_link_4"/>
    <limit effort="30" lower="-3.14159265359" upper="3.14159265359" velocity="5"/>
  </joint>
<link name="jaco_link_4">
    <inertial>
      <mass value="1"/>
      <inertia ixx="1" ixy="0" ixz="0" iyy="1" iyz="0" izz="1"/>
      <origin/>
    </inertial>
    <visual>
      <material name="JacoGrey"/>
      <origin rpy="0 0 -1.570796327" xyz="0 0 -0.042276823"/>
      <geometry>
        <mesh filename="package://jaco_description/meshes/mico_joint_5.DAE" scale="1 1 1"/>
      </geometry>
    </visual>
    <collision>
      <origin rpy="0 0 -1.570796327" xyz="0 0 -0.042276823"/>
      <geometry>
        <mesh filename="package://jaco_description/meshes/mico_joint_5.DAE" scale="1 1 1"/>
      </geometry>
    </collision>
  </link>
  <gazebo reference="jaco_link_4">
    <material>Gazebo/Blue</material>
    <turnGravityOff>false</turnGravityOff>
  </gazebo>

 <joint name="jaco_joint_5" type="revolute">
     <origin rpy="1.1278 0 0" xyz="0 -0.079855 0.03998"/>
    <axis xyz="0 0 1"/>
    <parent link="jaco_link_4"/>
    <child link="jaco_link_5"/>
    <limit effort="30" lower="-3.14159265359" upper="3.14159265359" velocity="5"/>
  </joint>
  <link name="jaco_link_5">
    <inertial>
      <mass value="1.0"/>
      <inertia ixx="1" ixy="0" ixz="0" iyy="1" iyz="0" izz="1"/>
      <origin/>
    </inertial>
    <visual>
      <material name="JacoGrey"/>
 <origin rpy="0 -0.959931089 1.570796327" xyz="0 0 -0.042276823"/>
      <geometry>
        <mesh filename="package://jaco_description/meshes/mico_joint_6.DAE" scale="1 1 1"/>
      </geometry>
    </visual>
    <collision>
 <origin rpy="0 -0.959931089 1.570796327" xyz="0 0 -0.042276823"/>
      <geometry>
        <mesh filename="package://jaco_description/meshes/mico_joint_6.DAE" scale="1 1 1"/>
      </geometry>
    </collision>
  </link>
  <gazebo reference="jaco_link_5">
    <material>Gazebo/Red</material>
    <turnGravityOff>false</turnGravityOff>
  </gazebo>

<joint name="jaco_joint_6" type="revolute">
    <!--origin xyz="0 -0.186174274 0.13036063" rpy="0.959931089 0 0"/-->
    <origin rpy="-0.959931089 0 3.1415926535897931" xyz="0 -0.186174274 0.13036063"/>
    <!--<origin xyz="0 0 0" rpy="0 0 -3.14"/>-->
    <axis xyz="0 0 -1"/>
    <parent link="jaco_link_5"/>
    <child link="jaco_link_6"/>
    <limit effort="30" lower="-3.14159265359" upper="3.14159265359" velocity="5"/>
  </joint>
  <link name="jaco_link_6">
    <inertial>
      <mass value="0.3"/>
      <inertia ixx="1" ixy="0" ixz="0" iyy="1" iyz="0" izz="1"/>
      <origin/>
    </inertial>
    <visual>
      <material name="JacoGrey"/>
      <origin rpy="0 0 -3.1415926535897931" xyz="0 0 -0.1850"/>
      <!--<origin xyz="0 0 -0.1850" rpy="0 0 0"/>      -->
      <geometry>
        <mesh filename="package://jaco_description/meshes/mico_joint_7.DAE" scale="1 1 1"/>
      </geometry>
    </visual>
    <collision>
      <origin rpy="0 0 -3.1415926535897931" xyz="0 0 -0.1850"/>
      <!--<origin xyz="0 0 -0.1850" rpy="0 0 0"/>-->
      <geometry>
        <mesh filename="package://jaco_description/meshes/mico_joint_7.DAE" scale="1 1 1"/>
      </geometry>
    </collision>
  </link>
  <gazebo reference="jaco_link_6">
    <material>Gazebo/Blue</material>
    <turnGravityOff>false</turnGravityOff>
  </gazebo>
  <joint name="jaco_gripper_tool_frame_joint" type="fixed">
    <parent link="jaco_link_6"/>
    <child link="jaco_gripper_tool_frame"/>
    <origin rpy="0.23 -1.570796327 1.570796327" xyz="0 0 -0.08"/>
  </joint>
  <link name="jaco_gripper_tool_frame">
    <!-- This is the coordinate system of the tool (this is the position
         used in IK etc., relative to the base frame); there is no actual
         arm part attached to this link -->
  </link>

<joint name="jaco_finger_joint_1" type="revolute">
    <!--origin xyz="-0.036 -0.021 -0.07" rpy="0 0 0"/-->
    <!-- changed becuase it look funny in simulation-->
    <origin rpy="0 0 -1.57" xyz="-0.0009 0.03610 -0.079888"/>
    <axis xyz="0 1 0"/>
    <parent link="jaco_link_6"/>
    <child link="jaco_finger_link_1"/>
    <limit effort="30" lower="0.004" upper="1.044" velocity="5"/>
  </joint>
  <link name="jaco_finger_link_1">
    <inertial>
      <mass value="0.05"/>
      <inertia ixx="1" ixy="0" ixz="0" iyy="1" iyz="0" izz="1"/>
      <origin/>
    </inertial>
    <visual>
      <origin rpy="0 0 0" xyz="0 0 0"/>
      <geometry>
        <mesh filename="package://jaco_description/meshes/finger.stl" scale="1 1 1"/>
      </geometry>
    </visual>
    <collision>
      <origin rpy="0 0 0" xyz="0 0 0"/>
      <geometry>
        <mesh filename="package://jaco_description/meshes/finger.stl" scale="1 1 1"/>
      </geometry>
    </collision>
  </link>
  <gazebo reference="jaco_finger_link_1">
    <material>Gazebo/Red</material>
    <turnGravityOff>false</turnGravityOff>
  </gazebo>
  <joint name="jaco_finger_joint_2" type="revolute">
    <!--origin xyz="-0.036 0.021 -0.07" rpy="0 0 0"/-->
    <origin rpy="0 0 1.57" xyz="-0.0009 -0.03610 -0.079888"/>
    <axis xyz="0 1 0"/>
    <parent link="jaco_link_6"/>
    <child link="jaco_finger_link_2"/>
    <limit effort="30" lower="0.004" upper="1.044" velocity="5"/>
  </joint>
  <link name="jaco_finger_link_2">
    <inertial>
      <mass value="0.05"/>
      <inertia ixx="1" ixy="0" ixz="0" iyy="1" iyz="0" izz="1"/>
      <origin/>
    </inertial>
    <visual>
      <origin rpy="0 0 0" xyz="0 0 0"/>
      <geometry>
        <mesh filename="package://jaco_description/meshes/finger.stl" scale="1 1 1"/>
      </geometry>
    </visual>
    <collision>
      <origin rpy="0 0 0" xyz="0 0 0"/>
      <geometry>
        <mesh filename="package://jaco_description/meshes/finger.stl" scale="1 1 1"/>
      </geometry>
    </collision>
  </link>
  <gazebo reference="jaco_finger_link_2">
    <material>Gazebo/Red</material>
    <turnGravityOff>false</turnGravityOff>
  </gazebo>


</robot>
